<?xml version="1.0"?>
<mujoco>
  <compiler angle="radian" meshdir="assets" autolimits="true"/>
  <asset>
    <material name="gray" rgba="0.4 0.4 0.4 1"/>
    <material name="yellow" rgba="0.866667 0.866667 0.0509804 1"/>
    <material name="light_orange" rgba="1 0.749 0 1"/>
    <material name="green" rgba="0.11 1 0 0.2"/>
    <mesh file="dip.stl"/>
    <mesh file="pip.stl"/>
    <mesh file="fingertip.stl"/>
    <mesh file="mcp_joint.stl"/>
  </asset>
  <default>
    <default class="finger">
      <material specular="0.5" shininess="0.25"/>
      <default class="visual">
        <geom type="mesh" contype="0" conaffinity="0" group="2"/>
      </default>
      <default class="collision_box">
        <geom group="3" type="box" mass="0" material="green"/>
      </default>
      <joint axis="0 0 -1" damping="2000"/>
    </default>
  </default>
  <worldbody>
    <body name="knuckle" >
      <joint name="j0" range="-0.314 2.23"/>
      <inertial mass="0.044" pos="0 0 0" diaginertia="1.47756e-05 1.31982e-05 6.0802e-06"/>
      <geom class="visual" pos="0.0084069 0.00776624 0.0146574" quat="1 0 0 0" mesh="mcp_joint" material="gray"/>
      <geom name="knuckle_b_1" class="collision_box" pos="0.0 0.008 0.015" euler="0 0 0" size="0.012 0.015 0.02"/>
      <geom name="knuckle_b_2" class="collision_box" pos="-0.03 0.04 0.018" euler="0 0 0" size="0.015 0.025 0.015"/>
      <body name="proximal" pos="-0.0122 0.0381 0.0145" quat="0.5 -0.5 -0.5 0.5">
        <joint name="j1" range="-1.047 1.047"/>
        <inertial mass="0.032" pos="0 0 0" diaginertia="4.7981e-06 4.23406e-06 2.86184e-06"/>
        <geom class="visual" pos="0.00964336 0.0003 0.000784034" quat="0.5 -0.5 -0.5 -0.5" mesh="pip" material="yellow"/>
        <geom name="proximal_b_1" class="collision_box" pos="0.01 0.0 -0.013" euler="0 0 0" size="0.02 0.015 0.01"/>
        <body name="middle" pos="0.015 0.0143 -0.013" quat="0.5 0.5 -0.5 0.5">
          <joint name="j2" range="-0.506 1.885"/>
          <inertial mass="0.037" pos="0 0 0" diaginertia="6.68256e-06 6.24841e-06 5.02002e-06"/>
          <geom class="visual" pos="0.0211334 -0.00843212 0.00978509" quat="0 -1 0 0" mesh="dip" material="yellow"/>
          <geom name="middle_b_1" class="collision_box" pos="0.0105 -0.034 0.015" euler="0 0 0" size="0.02 0.014 0.015"/>
          <body name="distal" pos="-4.08806e-09 -0.0361 0.0002">
            <joint name="j3" range="-0.366 2.042"/>
            <inertial mass="0.016" pos="0 0 0" diaginertia="3.37527e-06 2.863e-06 1.54873e-06"/>
            <geom class="visual" pos="0.0132864 -0.00611424 0.0145" quat="0 1 0 0" mesh="fingertip" material="yellow"/>
            <geom name="distal_b_1" class="collision_box" pos="0.0009 -0.034 0.0145" euler="0 0 0" size="0.012 0.014 0.012"/>
          </body>
        </body>
      </body>
    </body>
  </worldbody>
  <actuator>
    <position name="actuator1" joint="j0" kp="2000"/>
    <position name="actuator2" joint="j1" kp="2000"/>
    <position name="actuator3" joint="j2" kp="2000"/>
    <position name="actuator4" joint="j3" kp="2000"/>
  </actuator>
</mujoco>
